Workbook

Sheet Запрос Данных для расчета
B1: Запрос данных для расчета себестоимости СНК (прямые производственные расходы)
D2: Комментарий.
A3: 1. | B3: Наименование продукции | C3: ВМСН.713264.002 - Гайка
A4: 2. | B4: Количество едениц выпущенной продукции. Выпуск, шт. | C4: 1
A5: 3. | B5: Название цеха | C5: Участок производства изделий из пластмасс
A6: 4. | B6: Название станка | C6: Picaso Desinger X Series 2
A7: 4.1. | B7: Номинальная мощность станка по паспорту, кв*ч | C7: 0.7
A8: 4.2. | B8: Кол-во часов работы станка при вышеуказанном выпуске в строке 2) | C8: 1 ч 13 м
A9: 5. | B9: Материал/ Комплектующие | C9: ХХХХХХХХХХХХХ
A10: 5.1. | B10: Название сырья или материала | C10: АВS GF12 (Titan)
A11: 5.1.1. | B11: Ед.измерения материалов | C11: кг.
A12: 5.1.2. | B12: Расход сырья на 1 единицу изделия | C12: 0.019
A13: 5.2. | B13: Название сырья или материала (указывается, если используем более одного вида сырья)
A14: 5.2.1. | B14: Ед.измерения материалов
A15: 5.2.2. | B15: Расход сырья на 1 единицу изделия
A16: 5.3. | B16: Название сырья или материала (указывается, если используем более одного вида сырья)
A17: 5.3.1. | B17: Ед.измерения материалов
A18: 5.3.2. | B18: Расход сырья на 1 единицу изделия
A19: 5.4. | B19: Название сырья или материала
A20: 5.4.1. | B20: Ед.измерения материалов
A21: 5.4.2. | B21: Расход сырья на 1 единицу изделия
A22: 6. | B22: Трудозатраты | C22: ХХХХХХХХХХХХХ
A23: 6.1. | B23: Должность производственного рабочего | C23: Оператор оборудования трехмерной печати /Участок производства изделий из пластмасс /
A24: 6.1.1. | B24: Количество человек должности(указанной в пункте 6.1.) производят работу по выпуску (указанному в пункте 2.)изделий. | C24: 1
A25: 6.1.2. | B25: Количество часов на изготовление деталей всего выпуска одного вида изделия (количество деталей выпуска, указано в пункте 2.). Пример. Работало два человека, должность у которых одинаковая "Оператор лазерных установок 3 разряда /Участок механической обработки". Работали одновременно одну смену и вместе изготовили 100 штук деталей. Нужно указать в пункте 2. "100"; в пункте 6.1.1. "2 человека"; в пункте 6.1.2."11,00 часов". | C25: 1 ч 13 м
A26: 6.1.3. | B26: (Для мех.цеха, при производстве изделий комплектом на одной раскладке). Количество часов на партию изделий в одной раскладке. Если заполняется данная ячейка, предыдущая не заполняется. На все изделия при этом, используемые в раскладке, должны быть заполнены подобные таблицы)
A27: 6.2. | B27: Должность производственного рабочего, (указывается , если работы производятся более, чем одним человеком)
A28: 6.2.1. | B28: Количество человек должности(указанной в пункте 6.2.) производят работу по выпуску (указанному в пункте 2.)изделий.
A29: 6.2.2. | B29: Количество часов на изготовление деталей всего выпуска одного вида изделия (количество деталей выпуска, указано в пункте 2.).
A30: 6.2.3. | B30: (Для мех.цеха, при производстве изделий комплектом на одной раскладке). Количество часов на партию изделий в одной раскладке. Если заполняется данная ячейка, предыдущая не заполняется. На все изделия при этом, используемые в раскладке, должны быть заполнены подобные таблицы)
A31: 6.3. | B31: Должность производственного рабочего, (указывается , если работы производятся более, чем одним человеком)
A32: 6.3.1. | B32: Количество человек должности(указанной в пункте 6.3.) производят работу по выпуску (указанному в пункте 2.)изделий.
A33: 6.3.2. | B33: Количество часов на изготовление деталей всего выпуска одного вида изделия (количество деталей выпуска, указано в пункте 2.).
A34: 6.3.3. | B34: (Для мех.цеха, при производстве изделий комплектом на одной раскладке). Количество часов на партию изделий в одной раскладке. Если заполняется данная ячейка, предыдущая не заполняется. На все изделия при этом, используемые в раскладке, должны быть заполнены подобные таблицы)
A35: 7. | B35: Матрица/ Жертвенный стол | C35: ХХХХХХХХХХХХХ
A36: 7.1. | B36: Стоимость покупки мартрицы/ Стоимость жертвенного стола, руб.
A37: 7.1.1. | B37: Ресурс матрицы, шт
A38: 7.1.1. | B38: Ресурс матрицы/ жертвенного стола, часов
A39: 8. | B39: Упаковка | C39: ХХХХХХХХХХХХХ
A40: 8.1. | B40: Наименование номенклатуры упаковки.
...

Sheet Оборудоание
A1: оборудование | B1: мощность
A2: Picaso Desinger X Series 2 | B2: 0.7
A3: Лазерный станок Wattsan 1610 LT | B3: 4
A4: Фрезерный станок Wattsan 1325 А1 | B4: 3.5
A5: 3-х осевой центр | B5: 8
A6: 5-ти осевой центр | B6: 15

Sheet Расчет
E1: Материалы, ч.т. | J1: Работы, в т.ч | O1: Матрица, в .т.ч. | R1: Амортизация, в т.ч. | V1: Электроэнергия, в т.ч. | Z1: Упаковка, в .ч.
A2: Наименование продукции | C2: Итого, на 1 ед, руб. | D2: Количество едениц выпущенной продукции. Выпуск, шт. | E2: Название сырья или материала | F2: Ед.измерения материалов | G2: Расход сырья на 1 единицу изделия | H2: Цена, руб без НДС | I2: Сырьевая с/с ед. руб. без НДС | J2: Должность производственного рабочего | K2: Количество человек производящих работу по выпуску всего объема изделий(см. п. 2.) | L2: Количество часов на изготовление деталей всего выпуска одного вида изделия | M2: Стоимость часа работы по ФОТ с учетом отчислений в фонды( Кф=1,317), (Кф рабочих часов в месяц = 1/165) | N2: Заработная плата на ед. изделия, руб. | O2: Стоимость покупки мартрицы, на 20 000 изделий | P2: Ресурс матрицы, шт | Q2: Стоимость матрицы на единицу, руб | R2: Наименование оборудования | S2: Количество часов работы станка/Оборудования | T2: Амортизация в час ( Кф=ОСост.ст./Мес.исп./242 часов в месяц | U2: Амотризация | V2: Мощность оборудования | W2: Кол-во часов использования | X2: Стоимость 1 Квт/Ч | Y2: Затраты на электроэнергию, руб | Z2: Наименование номенклатуры упаковки, указывается, если используется более одного вида упаковки. | AA2: Ед.измерения | AB2: Кол-во упаковки на 1 ед.продукции | AC2: Цена, руб без НДС | AD2: Упаковка, руб без НДС
A3: 1. | C3: 2. | D3: 2. | E3: 5.1. | F3: 5.1. | G3: 5.2. | J3: 6.1. | K3: 6.1.1. | L3: 6.1.2. | O3: 7.1. | P3: 7.1.1. | R3: 4. | S3: 4.2. | V3: 4.1. | W3: 4.2. | Z3: 8.1. | AA3: 8.1.1. | AB3: 8.1.2.
A4: =VLOOKUP(A$3,'Запрос Данных для расчета'!$A:$C,3,FALSE) -> ВМСН.713264.002 - Гайка | C4: =SUMIF($B$5:$B$100,"",C$5:C$100) -> #DIV/0! | D4: =VLOOKUP(D$3,'Запрос Данных для расчета'!$A:$C,3,FALSE) -> 1 | I4: =SUMIF($B$5:$B$100,"",I$5:I$100) -> 0 | N4: =SUMIF($B$5:$B$100,"",N$5:N$100) -> 733.96011 | Q4: =SUMIF($B$5:$B$100,"",Q$5:Q$100) -> #DIV/0! | U4: =SUMIF($B$5:$B$100,"",U$5:U$100) -> #N/A | Y4: =SUMIF($B$5:$B$100,"",Y$5:Y$100) -> 5.25 | AD4: =SUMIF($B$5:$B$100,"",AD$5:AD$100) -> 0
A5: Название сырья или материала | C5: =SUMIF(B:B,A5,C:C) -> 0 | D5: x | I5: =SUM(I6:I9) -> 0 | J5: x | K5: x | L5: x | M5: x | N5: x | O5: x | P5: x | Q5: x | R5: x | S5: x | U5: x | V5: x | W5: x | X5: x | Y5: x | Z5: x | AA5: x | AB5: x | AC5: x | AD5: x
A6: =E6 -> АВS GF12 (Titan) | B6: Название сырья или материала | C6: =I6 -> 0 | E6: =VLOOKUP(E$3,'Запрос Данных для расчета'!$A:$C,3,FALSE) -> АВS GF12 (Titan) | F6: =VLOOKUP(F$2,'Запрос Данных для расчета'!$B:$C,2,FALSE) -> кг. | G6: =VLOOKUP(G$2,'Запрос Данных для расчета'!$B:$C,2,FALSE) -> 0.019 | H6: =SUMIF('Справочник цен, ЗП '!$A:$A,E6,'Справочник цен, ЗП '!$C:$C) -> 0 | I6: =G6*H6 -> 0 | J6: х | K6: х | L6: х | M6: х | N6: х | V6: x | W6: x | X6: x | Y6: x | Z6: x | AA6: x | AB6: x | AC6: x | AD6: x
A7: =E7 -> 0 | B7: Название сырья или материала | C7: =I7 -> 0 | E7: =VLOOKUP("5.2.",'Запрос Данных для расчета'!$A:$C,3,FALSE) -> 0 | F7: =VLOOKUP("5.2.1.",'Запрос Данных для расчета'!$A:$C,3,FALSE) -> 0 | G7: =VLOOKUP("5.2.2.",'Запрос Данных для расчета'!$A:$C,3,FALSE) -> 0 | H7: =SUMIF('Справочник цен, ЗП '!A:A,E7,'Справочник цен, ЗП '!C:C) -> 0 | I7: =G7*H7 -> 0 | J7: х | K7: х | L7: х | M7: х | N7: х | O7: х | P7: х | Q7: х | R7: х | S7: х | U7: х | V7: х | W7: х | X7: х | Y7: х | Z7: х | AA7: х | AB7: х | AC7: х | AD7: х
A8: =E8 -> 0 | B8: Название сырья или материала | C8: =I8 -> 0 | E8: =VLOOKUP("5.3.",'Запрос Данных для расчета'!$A:$C,3,FALSE) -> 0 | F8: =VLOOKUP("5.3.1.",'Запрос Данных для расчета'!$A:$C,3,FALSE) -> 0 | G8: =VLOOKUP("5.3.2.",'Запрос Данных для расчета'!$A:$C,3,FALSE) -> 0 | H8: =SUMIF('Справочник цен, ЗП '!A:A,E8,'Справочник цен, ЗП '!C:C) -> 0 | I8: =G8*H8 -> 0 | J8: х | K8: х | L8: х | M8: х | N8: х | O8: х | P8: х | Q8: х | R8: х | S8: х | U8: х | V8: х | W8: х | X8: х | Y8: х | Z8: х | AA8: х | AB8: х | AC8: х | AD8: х
A9: =E9 -> 0 | B9: Название сырья или материала | C9: =I9 -> 0 | E9: =VLOOKUP("5.4.",'Запрос Данных для расчета'!$A:$C,3,FALSE) -> 0 | F9: =VLOOKUP("5.4.1.",'Запрос Данных для расчета'!$A:$C,3,FALSE) -> 0 | G9: =VLOOKUP("5.4.2.",'Запрос Данных для расчета'!$A:$C,3,FALSE) -> 0 | H9: =SUMIF('Справочник цен, ЗП '!A:A,E9,'Справочник цен, ЗП '!C:C) -> 0 | I9: =G9*H9 -> 0 | J9: х | K9: х | L9: х | M9: х | N9: х | O9: х | P9: х | Q9: х | R9: х | S9: х | U9: х | V9: х | W9: х | X9: х | Y9: х | Z9: х | AA9: х | AB9: х | AC9: х | AD9: х
A10: Заработная плата | C10: =SUMIF(B:B,A10,C:C) -> 733.96011 | D10: x | I10: x | N10: =SUM(N11:N13) -> 733.96011 | Q10: x | U10: x | Y10: x | AD10: x
A11: =J11 -> Оператор оборудования трехмерной печати /Участок производства изделий из пластмасс / | B11: Заработная плата | C11: =N11 -> 733.96011 | E11: х | F11: х | G11: х | H11: х | I11: х | J11: =VLOOKUP(J$3,'Запрос Данных для расчета'!$A:$C,3,FALSE) -> Оператор оборудования трехмерной печати /Участок производства изделий из пластмасс / | K11: =VLOOKUP(K$3,'Запрос Данных для расчета'!$A:$C,3,FALSE) -> 1 | L11: =VLOOKUP(L$3,'Запрос Данных для расчета'!$A:$C,3,FALSE) -> 1 ч 13 м | M11: =VLOOKUP(J11,'Справочник цен, ЗП '!H:K,4,FALSE) -> 733.96011 | N11: =PRODUCT(K11:M11)/$D$4 -> 733.96011 | O11: х | P11: х | Q11: х | R11: х | S11: х | U11: х | V11: х | W11: х | X11: х | Y11: х | Z11: х | AA11: х | AB11: х | AC11: х | AD11: х
A12: =J12 -> 0 | B12: Заработная плата | C12: =N12 -> 0 | E12: х | F12: х | G12: х | H12: х | I12: х | J12: =VLOOKUP("6.2.",'Запрос Данных для расчета'!$A:$C,3,FALSE) -> 0 | K12: =VLOOKUP("6.2.1.",'Запрос Данных для расчета'!$A:$C,3,FALSE) -> 0 | L12: =VLOOKUP("6.2.2.",'Запрос Данных для расчета'!$A:$C,3,FALSE) -> 0 | M12: =SUMIF('Справочник цен, ЗП '!H:H,Расчет!J12,'Справочник цен, ЗП '!K:K) -> 0 | N12: =PRODUCT(K12:M12)/$D$4 -> 0 | O12: х | P12: х | Q12: х | R12: х | S12: х | U12: х | V12: х | W12: х | X12: х | Y12: х | Z12: х | AA12: х | AB12: х | AC12: х | AD12: х
A13: =J13 -> 0 | B13: Заработная плата | C13: =N13 -> 0 | E13: х | F13: х | G13: х | H13: х | I13: х | J13: =VLOOKUP("6.3.",'Запрос Данных для расчета'!$A:$C,3,FALSE) -> 0 | K13: =VLOOKUP("6.3.1.",'Запрос Данных для расчета'!$A:$C,3,FALSE) -> 0 | L13: =VLOOKUP("6.3.2.",'Запрос Данных для расчета'!$A:$C,3,FALSE) -> 0 | M13: =SUMIF('Справочник цен, ЗП '!H:H,Расчет!J13,'Справочник цен, ЗП '!K:K) -> 0 | N13: =PRODUCT(K13:M13)/$D$4 -> 0 | O13: х | P13: х | Q13: х | R13: х | S13: х | U13: х | V13: х | W13: х | X13: х | Y13: х | Z13: х | AA13: х | AB13: х | AC13: х | AD13: х
A14: Прочие прямые производственные расходы | C14: =SUMIF(B:B,A14,C:C) -> #DIV/0! | D14: x | I14: x | N14: x | Q14: =Q15 -> #DIV/0! | U14: =U16 -> #N/A | Y14: =SUM(Y15:Y18) -> 5.25 | AD14: =SUM(AD15:AD18) -> 0
A15: Матрица/ Жертвенный стол | B15: Прочие прямые производственные расходы | C15: =Q15 -> #DIV/0! | E15: х | F15: х | G15: х | H15: х | I15: х | J15: х | K15: х | L15: х | M15: х | N15: х | O15: =VLOOKUP(O$3,'Запрос Данных для расчета'!$A:$C,3,FALSE) -> 0 | P15: =SUMIF('Запрос Данных для расчета'!A:A,Расчет!$P$3,'Запрос Данных для расчета'!C:C) -> 0 | Q15: =IF(P15=100,O15/P15*(S16/D4),O15/P15) -> #DIV/0! | S15: х | U15: х | V15: х | W15: х | X15: х | Y15: х | Z15: х | AA15: х | AB15: х | AC15: х | AD15: х
A16: Амортизация | B16: Прочие прямые производственные расходы | C16: =U16 -> #N/A | E16: х | F16: х | G16: х | H16: х | I16: х | J16: х | K16: х | L16: х | M16: х | N16: х | O16: х | P16: х | Q16: х | R16: =VLOOKUP(R$3,'Запрос Данных для расчета'!$A:$C,3,FALSE) -> Picaso Desinger X Series 2 | S16: =VLOOKUP(S$3,'Запрос Данных для расчета'!$A:$C,3,FALSE) -> 1 ч 13 м | T16: =VLOOKUP(Расчет!$R16,'Справочник цен, ЗП '!$N:$Q,4,FALSE) -> #N/A | U16: =PRODUCT(S16:T16)/D4 -> #N/A | V16: х | W16: х | X16: х | Y16: х | Z16: х | AA16: х | AB16: х | AC16: х | AD16: х
A17: Электроэнергия | B17: Прочие прямые производственные расходы | C17: =Y17 -> 5.25 | E17: х | F17: х | G17: х | H17: х | I17: х | J17: х | K17: х | L17: х | M17: х | N17: х | O17: х | P17: х | Q17: х | R17: х | S17: х | U17: х | V17: =VLOOKUP(V$3,'Запрос Данных для расчета'!$A:$C,3,FALSE) -> 0.7 | W17: =VLOOKUP(W$3,'Запрос Данных для расчета'!$A:$C,3,FALSE) -> 1 ч 13 м | X17: 7.5 | Y17: =PRODUCT(V17:X17)/$D$4 -> 5.25 | Z17: х | AA17: х | AB17: х | AC17: х | AD17: х
A18: Упаковка | B18: Прочие прямые производственные расходы | C18: =AD18 -> 0 | E18: х | F18: х | G18: х | H18: х | I18: х | J18: х | K18: х | L18: х | M18: х | N18: х | O18: х | P18: х | Q18: х | R18: х | S18: х | U18: х | V18: х | W18: х | X18: х | Y18: х | Z18: =VLOOKUP(Z$3,'Запрос Данных для расчета'!$A:$C,3,FALSE) -> 0 | AA18: =VLOOKUP(AA$3,'Запрос Данных для расчета'!$A:$C,3,FALSE) -> 0 | AB18: =VLOOKUP(AB$3,'Запрос Данных для расчета'!$A:$C,3,FALSE) -> 0 | AC18: =SUMIF('Справочник цен, ЗП '!$A:$A,Z18,'Справочник цен, ЗП '!$C:$C) -> 0 | AD18: =PRODUCT(AB18:AC18) -> 0
A19: Накладные расходы, 20% | C19: =($C$6+$C$10+$C$14)*10% -> #DIV/0! | D19: x | I19: x | N19: x | Q19: x | U19: x | Y19: x | AD19: x
A20: Рентабельность, 10% | C20: =($C$6+$C$10+$C$14+$C$19)*10% -> #DIV/0! | D20: х | I20: x | N20: x | Q20: x | U20: x | Y20: x | AD20: x
A21: Налог на прибыль | C21: =(C6+C10+C14+C19+C20)*2% -> #DIV/0! | D21: x | I21: x | N21: x | Q21: x | U21: x | Y21: x | AD21: x
A22: НДС | C22: =(C6+C10+C14+C19+C20+C21)*20% -> #DIV/0! | D22: x | I22: x | N22: x | Q22: x | U22: x | Y22: x | AD22: x

Sheet Справочник для Запроса
A1: Ед.измерения | B1: Подразделение | C1: Должности | D1: Ресурс матрицы | E1: Ресурс жертвенного стола
A2: шт. | B2: Участок производства изделий из пластмасс | C2: Обработчик изделий из пластмасс 2 разряда /Участок производства изделий из пластмасс / | D2: 20000 | E2: 100
A3: метр | B3: Участок механической обработки | C3: Оператор оборудования трехмерной печати /Участок производства изделий из пластмасс /
A4: м2 | B4: Участок сборочных линий БВС | C4: Машинист вакуум-формовочной машины 2 разряда /Участок производства изделий из пластмасс /
A5: кг. | B5: Участок композитного производства | C5: Литейщик пластмасс 2 разряда /Участок производства изделий из пластмасс /
A6: п.метр | C6: Литейщик пластмасс 2 разряда /Участок производства изделий из пластмасс /
C7: Мастер /Участок производства изделий из пластмасс /
C8: Наладчик инжекционно-литьевой машины /Участок производства изделий из пластмасс /
C9: Наладчик инжекционно-литьевой машины /Участок производства изделий из пластмасс /
C10: Начальник участка /Участок производства изделий из пластмасс /
C11: Инженер-технолог /Участок производства изделий из пластмасс /
C12: Слесарь-сборщик летательных аппаратов 3 разряда /Участок механической обработки /
C13: Оператор лазерных установок 3 разряда /Участок механической обработки /
C14: Слесарь-сборщик летательных аппаратов 4 разряда /Участок механической обработки /
C15: Оператор лазерных установок 3 разряда /Участок механической обработки /
C16: Оператор станков с программным управлением 3 разряда /Участок механической обработки /
C17: Оператор станков с программным управлением 4 разряда /Участок механической обработки /
C18: Начальник смены /Участок механической обработки /
... C53: Начальник участка /Участок композитного производства/

Sheet Справочник цен, ЗП 
A1: Номенклатура | B1: Документ | C1: Цена | H1: Должность | I1: ЗП | J1: ЗП+ФОНД Кф=1,317 | K1: Стоимость часа работы Кф=1/165 часов в месяц | N1: Станок | O1: Закупочная стоимость | P1: Амортизация 02 счет | Q1: за час
A2: Micro JST GH1.25 150mm 9Р Single Connector 28AWG | B2: Приходная накладная 270 (вх. 6) от 12.02.2024 | C2: 97.5 | H2: Обработчик изделий из пластмасс 2 разряда /Участок производства изделий из пластмасс / | I2: 68966 | J2: =I2*1.317 -> 90828.222 | K2: =J2/165 -> 550.47407 | L2: =COUNTIF($H$1:H1,H2) -> 0 | N2: Wattsan 1325A1 | O2: =1057960.01/1.2-145210 -> 736423.34 | P2: 10679.48 | Q2: =P2/(21*11) -> 46.231515
A3: Доставка товара клиенту | B3: Дополнительные расходы 577 (вх. 3359) от 07.05.2024 | C3: 408.33 | H3: Оператор оборудования трехмерной печати /Участок производства изделий из пластмасс / | I3: 91954 | J3: =I3*1.317 -> 121103.42 | K3: =J3/165 -> 733.96011 | L3: =COUNTIF($H$1:H2,H3) -> 0 | N3: 3D принтер Bambu lab X1 | P3: 5712.57 | Q3: =P3/(21*11) -> 24.72974
A4: кабель USB | B4: Приходная накладная 5206 (вх. 116) от 22.10.2024 | C4: 166.67 | H4: Машинист вакуум-формовочной машины 2 разряда /Участок производства изделий из пластмасс / | I4: 91954 | J4: =I4*1.317 -> 121103.42 | K4: =J4/165 -> 733.96011 | L4: =COUNTIF($H$1:H3,H4) -> 0 | N4: 3D принтер Designer X PRO series 2 (1) (инв.номер БП-000014) | P4: 18500 | Q4: =P4/(21*11) -> 80.08658
A5: Комплект разработчика радиоканала, Microhard pMDDL2350 | B5: Приходная накладная 4262 (вх. 65) от 01.03.2024 (удален) (не проведен) | C5: 209416.67 | H5: Литейщик пластмасс 2 разряда /Участок производства изделий из пластмасс / | I5: 103449 | J5: =I5*1.317 -> 136242.33 | K5: =J5/165 -> 825.71111 | L5: =COUNTIF($H$1:H4,H5) -> 0 | N5: 3D принтер Designer X PRO series 2 (2) (инв.номер БП-000013) | P5: 17760 | Q5: =P5/(21*11) -> 76.883117
A6: Разъемы питания АКБ male 10 pin | B6: Приходная накладная 1193 (вх. 119) от 14.05.2024 | C6: 51.67 | H6: Литейщик пластмасс 2 разряда /Участок производства изделий из пластмасс / | I6: 91954 | J6: =I6*1.317 -> 121103.42 | L6: =COUNTIF($H$1:H5,H6) -> 1 | N6: 3D принтер Designer X PRO series 2 (3) (инв.номер БП-000015) | P6: 17760 | Q6: =P6/(21*11) -> 76.883117
A7: !!!!!!!!Футболка т.-синяя L (48-50) | B7: Приходная накладная 4334 (вх. 146164) от 10.07.2024 | C7: 422.87 | H7: Мастер /Участок производства изделий из пластмасс / | I7: 126437 | J7: =I7*1.317 -> 166517.53 | K7: =J7/165 -> 1009.1971 | L7: =COUNTIF($H$1:H6,H7) -> 0 | N7: 3D принтер Designer X series 2 (1) (инв.номер БП-000020) | P7: 8760 | Q7: =P7/(21*11) -> 37.922078
A8: (ДЛАБ.563561.006) Аккумуляторная батарея Сибирь 34000mAh | B8: Приходная накладная 5223 (вх. 20241022-2) от 23.10.2024 | C8: 33333.33 | H8: Наладчик инжекционно-литьевой машины /Участок производства изделий из пластмасс / | I8: 137931 | J8: =I8*1.317 -> 181655.13 | K8: =J8/165 -> 1100.9402 | L8: =COUNTIF($H$1:H7,H8) -> 0 | N8: 3D принтер Designer XL series 2 (1) (инв.номер БП-000016) | P8: 23291.31 | Q8: =P8/(21*11) -> 100.82818
A9: [Компьютер] C825475Ц-AMD Ryzen 7 5700G / MicroStar A520M-A PRO / 16GB / SSD 512GB | B9: Приходная накладная 1837 (вх. 2407-9) от 24.07.2024 | C9: 27902.5 | H9: Начальник участка /Участок производства изделий из пластмасс / | I9: 195402 | J9: =I9*1.317 -> 257344.43 | K9: =J9/165 -> 1559.6632 | L9: =COUNTIF($H$1:H8,H9) -> 0 | N9: 3D принтер Designer XL series 2 (2) (инв.номер БП-000017) | P9: 23291.31 | Q9: =P9/(21*11) -> 100.82818
A10: [Ноутбук] C835390Ц-NUC / I70000 Платформа / 2x16GB / SSD 1Tb | B10: Приходная накладная 1213 (вх. 36467Ц) от 16.05.2024 | C10: 86138.05 | H10: Инженер-технолог /Участок производства изделий из пластмасс / | I10: 413794 | J10: =I10*1.317 -> 544966.7 | K10: =J10/165 -> 3302.8285 | L10: =COUNTIF($H$1:H9,H10) -> 0 | N10: 3D принтер Designer XL series 2 (3) (инв.номер БП-000018) | P10: 23291.31 | Q10: =P10/(21*11) -> 100.82818
A11: 0,4 - 0,8 мм, Набор сверел для печатных плат 10шт | B11: Приходная накладная 3960 (вх. 0788454) от 16.09.2024 | C11: 325 | H11: Слесарь-сборщик летательных аппаратов 3 разряда /Участок механической обработки / | I11: 80460 | J11: =I11*1.317 -> 105965.82 | K11: =J11/165 -> 642.21709 | L11: =COUNTIF($H$1:H10,H11) -> 0 | N11: 3D принтер Designer XL series 2 (4) (инв.номер БП-000019) | P11: 23291.31 | Q11: =P11/(21*11) -> 100.82818
A12: 0,8 - 1,2 мм, Набор сверел для печатных плат 10шт | B12: Приходная накладная 3960 (вх. 0788454) от 16.09.2024 | C12: 325 | H12: Слесарь-сборщик летательных аппаратов 4 разряда /Участок механической обработки / | I12: 103449 | J12: =I12*1.317 -> 136242.33 | K12: =J12/165 -> 825.71111 | L12: =COUNTIF($H$1:H11,H12) -> 0 | N12: 3D принтер Designer Х series 2 (2) (инв.номер БП-000021) | P12: 8760 | Q12: =P12/(21*11) -> 37.922078
A13: 0.056мкФ X7R 50В 10% 0805 | B13: Приходная накладная 3960 (вх. 0788454) от 16.09.2024 | C13: 5 | H13: Оператор лазерных установок 3 разряда /Участок механической обработки / | I13: 114942 | J13: =I13*1.317 -> 151378.61 | K13: =J13/165 -> 917.44615 | L13: =COUNTIF($H$1:H12,H13) -> 0 | N13: 3D принтер Designer Х series 2 (3) (инв.номер БП-000022) | P13: 8760 | Q13: =P13/(21*11) -> 37.922078
A14: 0.1Вт 0603 5.1 кОм, 5%, Чип резистор (SMD)\Тайвань | B14: Приходная накладная 251 (вх. 0096455) от 06.02.2024 | C14: 0.54 | H14: Оператор лазерных установок 3 разряда /Участок механической обработки / | I14: 91954 | J14: =I14*1.317 -> 121103.42 | L14: =COUNTIF($H$1:H13,H14) -> 1 | N14: 3D принтер Designer Х series 2 (4) (инв.номер БП-000023) | P14: 8760 | Q14: =P14/(21*11) -> 37.922078
A15: 0.25Вт 1206 220 Ом, 1%, Чип резистор (SMD)\Тайвань | B15: Приходная накладная 3841 (вх. 0763559) от 10.09.2024 | C15: 5.83 | H15: Оператор станков с программным управлением 3 разряда /Участок механической обработки / | I15: 114942 | J15: =I15*1.317 -> 151378.61 | K15: =J15/165 -> 917.44615 | L15: =COUNTIF($H$1:H14,H15) -> 0 | N15: 3D принтер Designer Х series 2 (5) (инв.номер БП-000027) | P15: 8760 | Q15: =P15/(21*11) -> 37.922078
A16: 0.25Вт 1206 (перемычка) 0 Ом, 1%, Чип резистор (SMD) | B16: Приходная накладная 3960 (вх. 0788454) от 16.09.2024 | C16: 5 | H16: Оператор станков с программным управлением 4 разряда /Участок механической обработки / | I16: 149425 | J16: =I16*1.317 -> 196792.73 | K16: =J16/165 -> 1192.6832 | L16: =COUNTIF($H$1:H15,H16) -> 0 | N16: 3D принтер Designer Х series 2 (6) (инв.номер БП-000028) | P16: 8760 | Q16: =P16/(21*11) -> 37.922078
A17: 0.25Вт 1206 1 кОм, 5%, Чип резистор (SMD)\Тайвань | B17: Приходная накладная 251 (вх. 0096455) от 06.02.2024 | C17: 5 | H17: Начальник смены /Участок механической обработки / | I17: 126437 | J17: =I17*1.317 -> 166517.53 | K17: =J17/165 -> 1009.1971 | L17: =COUNTIF($H$1:H16,H17) -> 0 | M17: 8 | N17: 3D принтер Designer Х series 2 (7) (инв.номер БП-000029) | P17: 8760 | Q17: =P17/(21*11) -> 37.922078
A18: 0.25Вт 1206 10 кОм, 5%, Чип резистор (SMD)\Тайвань | B18: Приходная накладная 251 (вх. 0096455) от 06.02.2024 | C18: 5 | H18: Начальник смены /Участок механической обработки / | I18: 114942 | J18: =I18*1.317 -> 151378.61 | L18: =COUNTIF($H$1:H17,H18) -> 1 | N18: 3D принтер Designer Х series 2 (8) (инв.номер БП-000030) | P18: 8760 | Q18: =P18/(21*11) -> 37.922078
A19: 0.25Вт 1206 100 кОм, 5%, Чип резистор (SMD)\Тайвань | B19: Приходная накладная 251 (вх. 0096455) от 06.02.2024 | C19: 5 | H19: Мастер /Участок механической обработки / | I19: 149425 | J19: =I19*1.317 -> 196792.73 | K19: =J19/165 -> 1192.6832 | L19: =COUNTIF($H$1:H18,H19) -> 0 | N19: 3D принтер PICASO 3D Designer XL S2 | P19: 27666.67 | Q19: =P19/(21*11) -> 119.76913
A20: 0.25Вт 1206 100 Ом, 1%, Чип резистор (SMD) | B20: Приходная накладная 3960 (вх. 0788454) от 16.09.2024 | C20: 5 | H20: Мастер /Участок механической обработки / | I20: 137931 | J20: =I20*1.317 -> 181655.13 | L20: =COUNTIF($H$1:H19,H20) -> 1 | N20: 3D сканер Shining FreeScan UE Pro | P20: 101351.35 | Q20: =P20/(21*11) -> 438.75043
A21: 0.25Вт 1206 100 Ом, 1%, Чип резистор (SMD)\Тайвань | B21: Приходная накладная 251 (вх. 0096455) от 06.02.2024 | C21: 5 | H21: Сервисный инженер /Ремонтно-механический отдел/ | I21: 149425 | J21: =I21*1.317 -> 196792.73 | K21: =J21/165 -> 1192.6832 | L21: =COUNTIF($H$1:H20,H21) -> 0 | N21: 3D щуп Digital | P21: 9803.14 | Q21: =P21/(21*11) -> 42.437835
A22: 0.25Вт 1206 18 Ом, 1%, Чип резистор (SMD) | B22: Приходная накладная 3960 (вх. 0788454) от 16.09.2024 | C22: 5 | H22: Начальник участка /Участок механической обработки/ | I22: 206897 | J22: =I22*1.317 -> 272483.35 | K22: =J22/165 -> 1651.4142 | L22: =COUNTIF($H$1:H21,H22) -> 0 | N22: Ethernet-коммутатор MES2424P, 24 порта 10/100/1000BASE-T (PoE/PoE+), 4 порта - 1 | P22: 5145.8 | Q22: =P22/(21*11) -> 22.27619
A23: 0.25Вт 1206 20 кОм, 5%, Чип резистор (SMD)\Тайвань | B23: Приходная накладная 251 (вх. 0096455) от 06.02.2024 | C23: 5 | H23: Главный механик /Ремонтно-механический отдел/ | I23: 206897 | J23: =I23*1.317 -> 272483.35 | K23: =J23/165 -> 1651.4142 | L23: =COUNTIF($H$1:H22,H23) -> 0 | N23: Ethernet-коммутатор MES2424P, 24 порта 10/100/1000BASE-T (PoE/PoE+), 4 порта - 2 | P23: 5145.8 | Q23: =P23/(21*11) -> 22.27619
A24: 0.25Вт 1206 4.7 кОм, 1%, Чип резистор (SMD) | B24: Приходная накладная 3960 (вх. 0788454) от 16.09.2024 | C24: 5 | H24: Монтажник электрооборудования летательных аппаратов 2 разряда /Участок сборочных линий БВС/ | I24: 80460 | J24: =I24*1.317 -> 105965.82 | K24: =J24/165 -> 642.21709 | L24: =COUNTIF($H$1:H23,H24) -> 0 | N24: Ethernet-коммутатор MES5332A, 1x10/100/1000BASE-T (ООВ), 32x10GBASE-R (SFP+)/1000BASE-X (SFP)-1 | P24: 22347.33 | Q24: =P24/(21*11) -> 96.741688
A25: 0.25Вт 1206 47 кОм, 5%, Чип резистор (SMD)\Тайвань | B25: Приходная накладная 251 (вх. 0096455) от 06.02.2024 | C25: 5 | H25: Монтажник электрооборудования летательных аппаратов 2 разряда /Участок сборочных линий БВС/ | I25: 68966 | J25: =I25*1.317 -> 90828.222 | L25: =COUNTIF($H$1:H24,H25) -> 1 | N25: Ethernet-коммутатор MES5332A, 1x10/100/1000BASE-T (ООВ), 32x10GBASE-R (SFP+)/1000BASE-X (SFP)-2 | P25: 22347.33 | Q25: =P25/(21*11) -> 96.741688
A26: 0.25Вт 1206 5.1 кОм, 5%, Чип резистор (SMD)\Тайвань | B26: Приходная накладная 251 (вх. 0096455) от 06.02.2024 | C26: 5 | H26: Слесарь-сборщик летательных аппаратов 3 разряда /Участок сборочных линий БВС/ | I26: 91954 | J26: =I26*1.317 -> 121103.42 | K26: =J26/165 -> 733.96011 | L26: =COUNTIF($H$1:H25,H26) -> 0 | N26: GRD Сварочный стол 24.12 К 10ХСНД ТУ 173510,001-2022(высота стола 750мм) 1 (инв.номер БП-000034) | P26: 18037.39 | Q26: =P26/(21*11) -> 78.083939
A27: 0.25Вт 1206(перемычка) 0 Ом 5%, Чип резистор (SMD) \Тайвань | B27: Приходная накладная 251 (вх. 0096455) от 06.02.2024 | C27: 5 | H27: Слесарь-сборщик летательных аппаратов 3 разряда /Участок сборочных линий БВС/ | I27: 80460 | J27: =I27*1.317 -> 105965.82 | L27: =COUNTIF($H$1:H26,H27) -> 1 | N27: GRD Сварочный стол 24.12 К 10ХСНД ТУ 173510,001-2022(высота стола 750мм) 2 (инв.номер БП-000035) | P27: 18037.39 | Q27: =P27/(21*11) -> 78.083939
A28: 0430300001@MOLEX | B28: Приходная накладная 2141 (вх. 824633) от 20.08.2024 | C28: 1.68 | H28: Монтажник электрооборудования летательных аппаратов 3 разряда /Участок сборочных линий БВС/ | I28: 91954 | J28: =I28*1.317 -> 121103.42 | K28: =J28/165 -> 733.96011 | L28: =COUNTIF($H$1:H27,H28) -> 0 | N28: M18 FMS305-121 Акк. торцовочная пила 1 | P28: 20106.25 | Q28: =P28/(21*11) -> 87.040043
A29: 0603WAF1003T5E | B29: Приходная накладная 942 (вх. 794660) от 11.04.2024 | C29: 11.92 | H29: Монтажник электрооборудования летательных аппаратов 3 разряда /Участок сборочных линий БВС/ | I29: 80460 | J29: =I29*1.317 -> 105965.82 | L29: =COUNTIF($H$1:H28,H29) -> 1 | N29: M18 FMS305-121 Акк. торцовочная пила 2 | P29: 20106.25 | Q29: =P29/(21*11) -> 87.040043
A30: 0603WAF200JT5E | B30: Приходная накладная 1041 (вх. 797647) от 19.04.2024 | C30: 5.7 | H30: Слесарь-сборщик летательных аппаратов 4 разряда /Участок сборочных линий БВС/ | I30: 103449 | J30: =I30*1.317 -> 136242.33 | K30: =J30/165 -> 825.71111 | L30: =COUNTIF($H$1:H29,H30) -> 0 | N30: QNAP TS-h973AX-32G NAS сервер сетевое хранилище | P30: 7869.32 | Q30: =P30/(21*11) -> 34.06632
A31: 0603WAF2400T5E | B31: Приходная накладная 1041 (вх. 797647) от 19.04.2024 | C31: 5.7 | H31: Слесарь-сборщик летательных аппаратов 4 разряда /Участок сборочных линий БВС/ | I31: 91954 | J31: =I31*1.317 -> 121103.42 | L31: =COUNTIF($H$1:H30,H31) -> 1 | N31: Автомобиль GREAT WALL POER VIN:LGWDAE196PJ646874 | P31: 101964.8 | Q31: =P31/(21*11) -> 441.40606
A32: 0603WAF2800T5E | B32: Приходная накладная 1041 (вх. 797647) от 19.04.2024 | C32: 5.72 | H32: Монтажник электрооборудования летательных аппаратов 4 разряда /Участок сборочных линий БВС/ | I32: 103449 | J32: =I32*1.317 -> 136242.33 | K32: =J32/165 -> 825.71111 | L32: =COUNTIF($H$1:H31,H32) -> 0 | N32: Автомобиль GREAT WALL POER VIN:LGWDAE199PJ651096 | P32: 101964.8 | Q32: =P32/(21*11) -> 441.40606
A33: 0603WAF4122T5E | B33: Приходная накладная 1041 (вх. 797647) от 19.04.2024 | C33: 5.7 | H33: Монтажник электрооборудования летательных аппаратов 5 разряда /Участок сборочных линий БВС/ | I33: 114942 | J33: =I33*1.317 -> 151378.61 | K33: =J33/165 -> 917.44615 | L33: =COUNTIF($H$1:H32,H33) -> 0 | N33: Автомобиль LADA 21214 VIN XTA21240R2501424 | P33: 23490.99 | Q33: =P33/(21*11) -> 101.6926
A34: 0603WAF5102T5E | B34: Приходная накладная 1041 (вх. 797647) от 19.04.2024 | C34: 5.7 | H34: Слесарь-сборщик летательных аппаратов 5 разряда /Участок сборочных линий БВС/ | I34: 114942 | J34: =I34*1.317 -> 151378.61 | K34: =J34/165 -> 917.44615 | L34: =COUNTIF($H$1:H33,H34) -> 0 | N34: АККУМУЛЯТОРНАЯ ПОГРУЖНАЯ ЦИРКУЛЯРНАЯ ПИЛА MILWAUKEE M18 FUEL FPS55-0P | P34: 2717.06 | Q34: =P34/(21*11) -> 11.762165
A35: 0603WAF510JT5E | B35: Приходная накладная 1041 (вх. 797647) от 19.04.2024 | C35: 5.72 | H35: Начальник смены /Участок сборочных линий БВС/ | I35: 126437 | J35: =I35*1.317 -> 166517.53 | K35: =J35/165 -> 1009.1971 | L35: =COUNTIF($H$1:H34,H35) -> 0 | N35: Аппарат аргонодуговой сварки Сварог "Инвертор сварочный TIG 315P AC/DC MULTIWAVE PRO E202 | P35: 6350.44 | Q35: =P35/(21*11) -> 27.491082
A36: 0603WAF7501T5E | B36: Приходная накладная 942 (вх. 794660) от 11.04.2024 | C36: 5.79 | H36: Мастер /Участок сборочных линий БВС/ | I36: 137931 | J36: =I36*1.317 -> 181655.13 | K36: =J36/165 -> 1100.9402 | L36: =COUNTIF($H$1:H35,H36) -> 0 | N36: Белмаш Станок круглопильный с подвижным столом TS-250-ST1300 S194A (инв.номер БП-000024) | P36: 9039.13 | Q36: =P36/(21*11) -> 39.130433
A37: 100пФ NPO 50В 5% 0805 | B37: Приходная накладная 3960 (вх. 0788454) от 16.09.2024 | C37: 10.83 | H37: Начальник участка /Участок сборочных линий БВС/ | I37: 206897 | J37: =I37*1.317 -> 272483.35 | K37: =J37/165 -> 1651.4142 | L37: =COUNTIF($H$1:H36,H37) -> 0 | N37: Вакуум формовочная машина VF2010 (инв.номер БП-000043) | P37: 8074.79 | Q37: =P37/(21*11) -> 34.955801
A38: 100пФ NPO 50В 5% 1206 | B38: Приходная накладная 3960 (вх. 0788454) от 16.09.2024 | C38: 10.83 | H38: Контуровщик стеклопластиковых изделий /Участок композитного производства/ | I38: 103449 | J38: =I38*1.317 -> 136242.33 | K38: =J38/165 -> 825.71111 | L38: =COUNTIF($H$1:H37,H38) -> 0 | N38: Вакуумная камера МT-V900-FR (инв.номер БП-000048) | P38: 12471.31 | Q38: =P38/(21*11) -> 53.988355
A39: 100СМ Сервоудлинитель с разъёмами (JR) и фиксатором 26AWG (1шт) | B39: Приходная накладная 197 (вх. 30) от 09.01.2024 | C39: 208.33 | H39: Контуровщик стеклопластиковых изделий /Участок композитного производства/ | I39: 80460 | J39: =I39*1.317 -> 105965.82 | L39: =COUNTIF($H$1:H38,H39) -> 1 | N39: Вауумный насос VSV-300 | P39: 11434.72 | Q39: =P39/(21*11) -> 49.500952
A40: 1054500101 | B40: Приходная накладная 943 (вх. 794659) от 11.04.2024 | C40: 172.95 | H40: Формовщик стеклопластиковых изделий /Участок композитного производства/ | I40: 103449 | J40: =I40*1.317 -> 136242.33 | K40: =J40/165 -> 825.71111 | L40: =COUNTIF($H$1:H39,H40) -> 0 | N40: Вертикально-фрезерный станок мод. МС955 (инв.номер БП-000049) | P40: 178903.48 | Q40: =P40/(21*11) -> 774.47394
...
